const axios = require('axios');

// Configura√ß√£o base da API
const api = axios.create({
  baseURL: 'https://www.auxiliadorapay.shop/api',
  timeout: 10000,
  headers: {
    'Content-Type': 'application/json',
    'Accept': 'application/json'
  }
});

// Interceptor para requisi√ß√µes
api.interceptors.request.use(
  (config) => {
    console.log(`üöÄ Fazendo requisi√ß√£o: ${config.method?.toUpperCase()} ${config.url}`);
    return config;
  },
  (error) => {
    console.error('‚ùå Erro na requisi√ß√£o:', error.message);
    return Promise.reject(error);
  }
);

// Interceptor para respostas
api.interceptors.response.use(
  (response) => {
    console.log(`‚úÖ Resposta recebida: ${response.status} ${response.statusText}`);
    return response;
  },
  (error) => {
    console.error('‚ùå Erro na resposta:', handleApiError(error));
    return Promise.reject(error);
  }
);

// Fun√ß√£o para tratar erros da API
function handleApiError(error) {
  if (error.response) {
    // Erro de resposta do servidor (4xx, 5xx)
    const { status, data } = error.response;
    switch (status) {
      case 400:
        return `Requisi√ß√£o inv√°lida: ${data.message || 'Dados fornecidos s√£o inv√°lidos'}`;
      case 401:
        return 'N√£o autorizado: Verifique suas credenciais';
      case 403:
        return 'Acesso negado: Voc√™ n√£o tem permiss√£o para esta opera√ß√£o';
      case 404:
        return 'Recurso n√£o encontrado';
      case 422:
        return `Erro de valida√ß√£o: ${data.message || 'Dados n√£o puderam ser processados'}`;
      case 500:
        return 'Erro interno do servidor: Tente novamente mais tarde';
      default:
        return `Erro ${status}: ${data.message || 'Erro desconhecido'}`;
    }
  } else if (error.request) {
    // Erro de rede ou timeout
    return 'Erro de conex√£o: Verifique sua internet ou se o servidor est√° dispon√≠vel';
  } else {
    // Erro na configura√ß√£o da requisi√ß√£o
    return `Erro na configura√ß√£o: ${error.message}`;
  }
}

// Fun√ß√£o auxiliar para fazer requisi√ß√µes com tratamento de erro
async function makeRequest(requestFn, errorContext = '') {
  try {
    const response = await requestFn();
    return response.data;
  } catch (error) {
    const errorMessage = handleApiError(error);
    console.error(`‚ùå ${errorContext}: ${errorMessage}`);
    throw new Error(errorMessage);
  }
}

module.exports = {
  api,
  makeRequest,
  handleApiError
};